<?xml version="1.0" ?>
<robot name="ika" xmlns:xacro="http://www.ros.org/wiki/xacro">

<xacro:include filename="$(find ika_description)/urdf/materials.xacro" />
<xacro:include filename="$(find ika_description)/urdf/ika.trans" />
<xacro:include filename="$(find ika_description)/urdf/ika.gazebo" />
<xacro:include filename="$(find ika_description)/urdf/rplidar_s2.xacro"/>
<xacro:include filename="$(find ika_description)/urdf/d435_camera.xacro"/>
<link name="base_link">
  <inertial>
    <origin xyz="0.005414069729213678 -9.213349753885084e-05 0.18125650823624936" rpy="0 0 0"/>
    <mass value="33.27397338943597"/>
    <inertia ixx="1.776669" iyy="3.447502" izz="4.12897" ixy="-0.000217" iyz="8.1e-05" ixz="0.106412"/>
  </inertial>
  <visual>
    <origin xyz="0 0 0" rpy="0 0 0"/>
    <geometry>
      <mesh filename="file://$(find ika_description)/meshes/base_link.stl" scale="0.001 0.001 0.001"/>
    </geometry>
    <material name="silver"/>
  </visual>
  <collision>
    <origin xyz="0 0 0" rpy="0 0 0"/>
    <geometry>
      <mesh filename="file://$(find ika_description)/meshes/base_link.stl" scale="0.001 0.001 0.001"/>
    </geometry>
  </collision>
</link>

<!-- Lidar (RPLidar S2) -->
<xacro:rplidar_s2 parent="base_link" name="lidar" xyz="0.2 0 0.36" rpy="0 0.035 0"/>
<xacro:rplidar_s2_gazebo_plugin name="lidar"/>

<!-- Kamera (D435) -->
<xacro:realsense_d435 parent="base_link" name="camera" xyz="0.2 -0.10 0.37" rpy="0 0 0"/>
<xacro:d435_gazebo_plugins name="camera"/>

<link name="lazer_alt_v1_1">
  <inertial>
    <origin xyz="0.0014888107746208197 -0.0035899898514626357 0.10456339198720316" rpy="0 0 0"/>
    <mass value="16.247587853935794"/>
    <inertia ixx="0.136244" iyy="0.135351" izz="0.128752" ixy="0.000564" iyz="0.000306" ixz="0.003402"/>
  </inertial>
  <visual>
    <origin xyz="-0.000155 0.001158 -0.366945" rpy="0 0 0"/>
    <geometry>
      <mesh filename="file://$(find ika_description)/meshes/lazer_alt_v1_1.stl" scale="0.001 0.001 0.001"/>
    </geometry>
    <material name="silver"/>
  </visual>
  <collision>
    <origin xyz="-0.000155 0.001158 -0.366945" rpy="0 0 0"/>
    <geometry>
      <mesh filename="file://$(find ika_description)/meshes/lazer_alt_v1_1.stl" scale="0.001 0.001 0.001"/>
    </geometry>
  </collision>
</link>

<link name="lazer_kafa_v1_1">
  <inertial>
    <origin xyz="-0.0027014583019456073 -0.05982148023716494 -0.0011419657213441736" rpy="0 0 0"/>
    <mass value="8.010863664139112"/>
    <inertia ixx="0.026022" iyy="0.04774" izz="0.04586" ixy="3e-06" iyz="-2e-06" ixz="0.000606"/>
  </inertial>
  <visual>
    <origin xyz="-0.006368 0.101158 -0.476695" rpy="0 0 0"/>
    <geometry>
      <mesh filename="file://$(find ika_description)/meshes/lazer_kafa_v1_1.stl" scale="0.001 0.001 0.001"/>
    </geometry>
    <material name="silver"/>
  </visual>
  <collision>
    <origin xyz="-0.006368 0.101158 -0.476695" rpy="0 0 0"/>
    <geometry>
      <mesh filename="file://$(find ika_description)/meshes/lazer_kafa_v1_1.stl" scale="0.001 0.001 0.001"/>
    </geometry>
  </collision>
</link>

<link name="sag_montaj_v1__1__1">
  <inertial>
    <origin xyz="-0.44919019560547796 0.00875238591849753 -0.21462842041488556" rpy="0 0 0"/>
    <mass value="4.8161613365412785"/>
    <inertia ixx="0.040395" iyy="0.433816" izz="0.40114" ixy="0.000534" iyz="0.000255" ixz="-0.096748"/>
  </inertial>
  <visual>
    <origin xyz="0.002 0.39 -0.175" rpy="0 0 0"/>
    <geometry>
      <mesh filename="file://$(find ika_description)/meshes/sag_montaj_v1__1__1.stl" scale="0.001 0.001 0.001"/>
    </geometry>
    <material name="silver"/>
  </visual>
  <collision>
    <origin xyz="0.002 0.39 -0.175" rpy="0 0 0"/>
    <geometry>
      <mesh filename="file://$(find ika_description)/meshes/sag_montaj_v1__1__1.stl" scale="0.001 0.001 0.001"/>
    </geometry>
  </collision>
</link>

<link name="sol_montaj_1_v81_v1__1__1">
  <inertial>
    <origin xyz="-0.43495134921430906 -0.008654379051771854 -0.20911455415076846" rpy="0 0 0"/>
    <mass value="4.962424557602971"/>
    <inertia ixx="0.04574" iyy="0.473545" izz="0.4357" ixy="-0.000757" iyz="-0.000346" ixz="-0.109048"/>
  </inertial>
  <visual>
    <origin xyz="0.001 -0.389 -0.175762" rpy="0 0 0"/>
    <geometry>
      <mesh filename="file://$(find ika_description)/meshes/sol_montaj_1_v81_v1__1__1.stl" scale="0.001 0.001 0.001"/>
    </geometry>
    <material name="silver"/>
  </visual>
  <collision>
    <origin xyz="0.001 -0.389 -0.175762" rpy="0 0 0"/>
    <geometry>
      <mesh filename="file://$(find ika_description)/meshes/sol_montaj_1_v81_v1__1__1.stl" scale="0.001 0.001 0.001"/>
    </geometry>
  </collision>
</link>

<link name="sag_on_montaj_v1_1">
  <inertial>
    <origin xyz="0.23792899315908234 -0.1512484643207898 -0.1176233402579002" rpy="0 0 0"/>
    <mass value="4.823288970520174"/>
    <inertia ixx="0.026621" iyy="0.284354" izz="0.268742" ixy="0.001967" iyz="-0.001043" ixz="-0.011091"/>
  </inertial>
  <visual>
    <origin xyz="-0.271451 0.421 -0.036349" rpy="0 0 0"/>
    <geometry>
      <mesh filename="file://$(find ika_description)/meshes/sag_on_montaj_v1_1.stl" scale="0.001 0.001 0.001"/>
    </geometry>
    <material name="silver"/>
  </visual>
  <collision>
    <origin xyz="-0.271451 0.421 -0.036349" rpy="0 0 0"/>
    <geometry>
      <mesh filename="file://$(find ika_description)/meshes/sag_on_montaj_v1_1.stl" scale="0.001 0.001 0.001"/>
    </geometry>
  </collision>
</link>

<link name="sol_on_montaj_v1_1">
  <inertial>
    <origin xyz="0.2379600351489939 0.15126109990473752 -0.11763901703510032" rpy="0 0 0"/>
    <mass value="4.822659769811814"/>
    <inertia ixx="0.026605" iyy="0.28431" izz="0.268699" ixy="-0.001953" iyz="0.001036" ixz="-0.011108"/>
  </inertial>
  <visual>
    <origin xyz="-0.272451 -0.42 -0.037112" rpy="0 0 0"/>
    <geometry>
      <mesh filename="file://$(find ika_description)/meshes/sol_on_montaj_v1_1.stl" scale="0.001 0.001 0.001"/>
    </geometry>
    <material name="silver"/>
  </visual>
  <collision>
    <origin xyz="-0.272451 -0.42 -0.037112" rpy="0 0 0"/>
    <geometry>
      <mesh filename="file://$(find ika_description)/meshes/sol_on_montaj_v1_1.stl" scale="0.001 0.001 0.001"/>
    </geometry>
  </collision>
</link>

<link name="360_motaj_1">
  <inertial>
    <origin xyz="-8.866769190429835e-06 -0.08695266369407406 -0.13583838034513812" rpy="0 0 0"/>
    <mass value="1.7763238488718671"/>
    <inertia ixx="0.011308" iyy="0.004985" izz="0.007632" ixy="-1e-06" iyz="-0.003117" ixz="-0.0"/>
  </inertial>
  <visual>
    <origin xyz="-0.647652 -0.573 0.165088" rpy="0 0 0"/>
    <geometry>
      <mesh filename="file://$(find ika_description)/meshes/360_motaj_1.stl" scale="0.001 0.001 0.001"/>
    </geometry>
    <material name="silver"/>
  </visual>
  <collision>
    <origin xyz="-0.647652 -0.573 0.165088" rpy="0 0 0"/>
    <geometry>
      <mesh filename="file://$(find ika_description)/meshes/360_motaj_1.stl" scale="0.001 0.001 0.001"/>
    </geometry>
  </collision>
</link>

<link name="360_motaj__1__1">
  <inertial>
    <origin xyz="4.109019291154148e-06 0.09826426441801484 -0.1453382099052203" rpy="0 0 0"/>
    <mass value="3.5648016982449495"/>
    <inertia ixx="0.015238" iyy="0.006535" izz="0.010918" ixy="-0.0" iyz="0.003744" ixz="-0.0"/>
  </inertial>
  <visual>
    <origin xyz="-0.646929 0.574 0.165851" rpy="0 0 0"/>
    <geometry>
      <mesh filename="file://$(find ika_description)/meshes/360_motaj__1__1.stl" scale="0.001 0.001 0.001"/>
    </geometry>
    <material name="silver"/>
  </visual>
  <collision>
    <origin xyz="-0.646929 0.574 0.165851" rpy="0 0 0"/>
    <geometry>
      <mesh filename="file://$(find ika_description)/meshes/360_motaj__1__1.stl" scale="0.001 0.001 0.001"/>
    </geometry>
  </collision>
</link>

<link name="360_montaj_1">
  <inertial>
    <origin xyz="-8.430075911336488e-06 -0.08695261407749894 -0.13583771694543326" rpy="0 0 0"/>
    <mass value="1.7763227489896294"/>
    <inertia ixx="0.011308" iyy="0.004985" izz="0.007632" ixy="-1e-06" iyz="-0.003117" ixz="-0.0"/>
  </inertial>
  <visual>
    <origin xyz="0.613492 -0.38 0.163438" rpy="0 0 0"/>
    <geometry>
      <mesh filename="file://$(find ika_description)/meshes/360_montaj_1.stl" scale="0.001 0.001 0.001"/>
    </geometry>
    <material name="silver"/>
  </visual>
  <collision>
    <origin xyz="0.613492 -0.38 0.163438" rpy="0 0 0"/>
    <geometry>
      <mesh filename="file://$(find ika_description)/meshes/360_montaj_1.stl" scale="0.001 0.001 0.001"/>
    </geometry>
  </collision>
</link>

<link name="360_motaj__2__1">
  <inertial>
    <origin xyz="4.703063507305316e-06 0.09826428565158002 -0.14533858598365362" rpy="0 0 0"/>
    <mass value="3.5648027981271886"/>
    <inertia ixx="0.015238" iyy="0.006535" izz="0.010918" ixy="-0.0" iyz="0.003744" ixz="-0.0"/>
  </inertial>
  <visual>
    <origin xyz="0.614492 0.381 0.1642" rpy="0 0 0"/>
    <geometry>
      <mesh filename="file://$(find ika_description)/meshes/360_motaj__2__1.stl" scale="0.001 0.001 0.001"/>
    </geometry>
    <material name="silver"/>
  </visual>
  <collision>
    <origin xyz="0.614492 0.381 0.1642" rpy="0 0 0"/>
    <geometry>
      <mesh filename="file://$(find ika_description)/meshes/360_motaj__2__1.stl" scale="0.001 0.001 0.001"/>
    </geometry>
  </collision>
</link>

<link name="tekerlek_v1_1">
  <inertial>
    <origin xyz="3.577735860904596e-07 0.037255183382986556 4.4407855009920283e-07" rpy="0 0 0"/>
    <mass value="2.9370630820602988"/>
    <inertia ixx="0.012817" iyy="0.023197" izz="0.012817" ixy="-0.0" iyz="-0.0" ixz="0.0"/>
  </inertial>
  <visual>
    <origin xyz="0.613492 -0.348 0.328938" rpy="0 0 0"/>
    <geometry>
      <mesh filename="file://$(find ika_description)/meshes/tekerlek_v1_1.stl" scale="0.001 0.001 0.001"/>
    </geometry>
    <material name="silver"/>
  </visual>
  <collision>
    <origin xyz="0.613492 -0.348 0.328938" rpy="0 0 0"/>
    <geometry>
      <mesh filename="file://$(find ika_description)/meshes/tekerlek_v1_1.stl" scale="0.001 0.001 0.001"/>
    </geometry>
  </collision>
</link>

<link name="tekerlek_v1__1__1">
  <inertial>
    <origin xyz="4.826719001323199e-07 0.03725518338296885 -2.1793502147371413e-07" rpy="0 0 0"/>
    <mass value="2.9370630820602988"/>
    <inertia ixx="0.012817" iyy="0.023197" izz="0.012817" ixy="-0.0" iyz="-0.0" ixz="0.0"/>
  </inertial>
  <visual>
    <origin xyz="0.022046 -0.5205 0.316888" rpy="0 0 0"/>
    <geometry>
      <mesh filename="file://$(find ika_description)/meshes/tekerlek_v1__1__1.stl" scale="0.001 0.001 0.001"/>
    </geometry>
    <material name="silver"/>
  </visual>
  <collision>
    <origin xyz="0.022046 -0.5205 0.316888" rpy="0 0 0"/>
    <geometry>
      <mesh filename="file://$(find ika_description)/meshes/tekerlek_v1__1__1.stl" scale="0.001 0.001 0.001"/>
    </geometry>
  </collision>
</link>

<link name="tekerlek_v1__2__1">
  <inertial>
    <origin xyz="-1.0373574077515713e-07 0.03725518338296674 -1.9101605741589367e-07" rpy="0 0 0"/>
    <mass value="2.9370630820602988"/>
    <inertia ixx="0.012817" iyy="0.023197" izz="0.012817" ixy="-0.0" iyz="-0.0" ixz="0.0"/>
  </inertial>
  <visual>
    <origin xyz="-0.647652 -0.541 0.330588" rpy="0 0 0"/>
    <geometry>
      <mesh filename="file://$(find ika_description)/meshes/tekerlek_v1__2__1.stl" scale="0.001 0.001 0.001"/>
    </geometry>
    <material name="silver"/>
  </visual>
  <collision>
    <origin xyz="-0.647652 -0.541 0.330588" rpy="0 0 0"/>
    <geometry>
      <mesh filename="file://$(find ika_description)/meshes/tekerlek_v1__2__1.stl" scale="0.001 0.001 0.001"/>
    </geometry>
  </collision>
</link>

<link name="tekerlek_v1__3__1">
  <inertial>
    <origin xyz="-2.912088178375072e-07 -0.03724481661703771 3.649053607057695e-07" rpy="0 0 0"/>
    <mass value="2.9370630820602988"/>
    <inertia ixx="0.012817" iyy="0.023197" izz="0.012817" ixy="0.0" iyz="-0.0" ixz="0.0"/>
  </inertial>
  <visual>
    <origin xyz="-0.646929 0.542 0.331851" rpy="0 0 0"/>
    <geometry>
      <mesh filename="file://$(find ika_description)/meshes/tekerlek_v1__3__1.stl" scale="0.001 0.001 0.001"/>
    </geometry>
    <material name="silver"/>
  </visual>
  <collision>
    <origin xyz="-0.646929 0.542 0.331851" rpy="0 0 0"/>
    <geometry>
      <mesh filename="file://$(find ika_description)/meshes/tekerlek_v1__3__1.stl" scale="0.001 0.001 0.001"/>
    </geometry>
  </collision>
</link>

<link name="tekerlek_v1__4__1">
  <inertial>
    <origin xyz="4.826718991157719e-07 -0.03724481661703838 3.3798639814675013e-07" rpy="0 0 0"/>
    <mass value="2.9370630820602988"/>
    <inertia ixx="0.012817" iyy="0.023197" izz="0.012817" ixy="-0.0" iyz="-0.0" ixz="0.0"/>
  </inertial>
  <visual>
    <origin xyz="0.023046 0.5215 0.317651" rpy="0 0 0"/>
    <geometry>
      <mesh filename="file://$(find ika_description)/meshes/tekerlek_v1__4__1.stl" scale="0.001 0.001 0.001"/>
    </geometry>
    <material name="silver"/>
  </visual>
  <collision>
    <origin xyz="0.023046 0.5215 0.317651" rpy="0 0 0"/>
    <geometry>
      <mesh filename="file://$(find ika_description)/meshes/tekerlek_v1__4__1.stl" scale="0.001 0.001 0.001"/>
    </geometry>
  </collision>
</link>

<link name="tekerlek_1">
  <inertial>
    <origin xyz="3.577735889770395e-07 -0.03724481661706941 -3.352873534367973e-14" rpy="0 0 0"/>
    <mass value="2.9370630820602988"/>
    <inertia ixx="0.012817" iyy="0.023197" izz="0.012817" ixy="-0.0" iyz="-0.0" ixz="0.0"/>
  </inertial>
  <visual>
    <origin xyz="0.614492 0.349 0.3302" rpy="0 0 0"/>
    <geometry>
      <mesh filename="file://$(find ika_description)/meshes/tekerlek_1.stl" scale="0.001 0.001 0.001"/>
    </geometry>
    <material name="silver"/>
  </visual>
  <collision>
    <origin xyz="0.614492 0.349 0.3302" rpy="0 0 0"/>
    <geometry>
      <mesh filename="file://$(find ika_description)/meshes/tekerlek_1.stl" scale="0.001 0.001 0.001"/>
    </geometry>
  </collision>
</link>

<joint name="laser_alt" type="fixed">
  <origin xyz="0.000155 -0.001158 0.366945" rpy="0 0 0"/>
  <parent link="base_link"/>
  <child link="lazer_alt_v1_1"/>
  <axis xyz="0.0 0.0 1.0"/>
</joint>

<joint name="laser_ust" type="fixed">
  <origin xyz="0.006213 -0.1 0.10975" rpy="0 0 0"/>
  <parent link="lazer_alt_v1_1"/>
  <child link="lazer_kafa_v1_1"/>
  <axis xyz="0.0 -1.0 -0.0"/>
  <limit upper="0.523599" lower="-0.261799" effort="100" velocity="100"/>
</joint>

<joint name="sag_kol" type="fixed">
  <origin xyz="-0.002 -0.39 0.175" rpy="0 0 0"/>
  <parent link="base_link"/>
  <child link="sag_montaj_v1__1__1"/>
  <axis xyz="0.0 -1.0 0.0"/>
</joint>

<joint name="sol_kol" type="fixed">
  <origin xyz="-0.001 0.389 0.175762" rpy="0 0 0"/>
  <parent link="base_link"/>
  <child link="sol_montaj_1_v81_v1__1__1"/>
  <axis xyz="0.0 1.0 0.0"/>
</joint>

<joint name="sag_on_kol" type="fixed">
  <origin xyz="0.273451 -0.031 -0.138651" rpy="0 0 0"/>
  <parent link="sag_montaj_v1__1__1"/>
  <child link="sag_on_montaj_v1_1"/>
  <axis xyz="-0.0 -1.0 0.0"/>
  <limit upper="0.174533" lower="-0.174533" effort="100" velocity="100"/>
</joint>

<joint name="sol_on_kol" type="fixed">
  <origin xyz="0.273451 0.031 -0.13865" rpy="0 0 0"/>
  <parent link="sol_montaj_1_v81_v1__1__1"/>
  <child link="sol_on_montaj_v1_1"/>
  <axis xyz="0.0 1.0 -0.0"/>
  <limit upper="0.174533" lower="-0.174533" effort="100" velocity="100"/>
  
</joint>

<joint name="sol_on_360" type="continuous">
  <origin xyz="0.375201 0.153 -0.2022" rpy="0 0 0"/>
  <parent link="sol_on_montaj_v1_1"/>
  <child link="360_motaj_1"/>
  <axis xyz="0.0 0.0 -1.0"/>

</joint>

<joint name="sag_on_360" type="continuous">
  <origin xyz="0.375478 -0.153 -0.2022" rpy="0 0 0"/>
  <parent link="sag_on_montaj_v1_1"/>
  <child link="360_motaj__1__1"/>
  <axis xyz="-0.0 -0.0 -1.0"/>

</joint>

<joint name="sol_arka_360" type="continuous">
  <origin xyz="-0.612492 -0.009 -0.3392" rpy="0 0 0"/>
  <parent link="sol_montaj_1_v81_v1__1__1"/>
  <child link="360_montaj_1"/>
  <axis xyz="0.0 -0.0 -1.0"/>
</joint>

<joint name="sag_arka_360" type="continuous">
  <origin xyz="-0.612492 0.009 -0.3392" rpy="0 0 0"/>
  <parent link="sag_montaj_v1__1__1"/>
  <child link="360_motaj__2__1"/>
  <axis xyz="-0.0 -0.0 -1.0"/>
</joint>

<joint name="sol_arka_teker" type="continuous">
  <origin xyz="0.0 -0.032 -0.1655" rpy="0 0 0"/>
  <parent link="360_montaj_1"/>
  <child link="tekerlek_v1_1"/>
  <axis xyz="0.0 1.0 -0.0"/>
</joint>

<joint name="sol_orta_teker" type="continuous">
  <origin xyz="-0.294497 0.1005 -0.354" rpy="0 0 0"/>
  <parent link="sol_on_montaj_v1_1"/>
  <child link="tekerlek_v1__1__1"/>
  <axis xyz="0.0 1.0 -0.0"/>
</joint>

<joint name="sol_on_teker" type="continuous">
  <origin xyz="0.0 -0.032 -0.1655" rpy="0 0 0"/>
  <parent link="360_motaj_1"/>
  <child link="tekerlek_v1__2__1"/>
  <axis xyz="0.0 1.0 0.0"/>
</joint>

<joint name="sag_on_teker" type="continuous">
  <origin xyz="0.0 0.032 -0.166" rpy="0 0 0"/>
  <parent link="360_motaj__1__1"/>
  <child link="tekerlek_v1__3__1"/>
  <axis xyz="-0.0 1.0 -0.0"/>
</joint>

<joint name="sag_orta_teker" type="continuous">
  <origin xyz="-0.294497 -0.1005 -0.354" rpy="0 0 0"/>
  <parent link="sag_on_montaj_v1_1"/>
  <child link="tekerlek_v1__4__1"/>
  <axis xyz="-0.0 1.0 -0.0"/>
</joint>

<joint name="sag_arka_teker" type="continuous">
  <origin xyz="0.0 0.032 -0.166" rpy="0 0 0"/>
  <parent link="360_motaj__2__1"/>
  <child link="tekerlek_1"/>
  <axis xyz="0.0 1.0 0.0"/>
</joint>

<!-- ROS2 Control Interface -->
<ros2_control name="GazeboSystem" type="system">
    <hardware>
        <plugin>gazebo_ros2_control/GazeboSystem</plugin>
    </hardware>
    <!-- Steering joints (4 steerable wheels) -->
    <joint name="sol_on_360">
        <command_interface name="position"/>
        <state_interface name="position"/>
        <state_interface name="velocity"/>
    </joint>
    <joint name="sag_on_360">
        <command_interface name="position"/>
        <state_interface name="position"/>
        <state_interface name="velocity"/>
    </joint>
    <joint name="sol_arka_360">
        <command_interface name="position"/>
        <state_interface name="position"/>
        <state_interface name="velocity"/>
    </joint>
    <joint name="sag_arka_360">
        <command_interface name="position"/>
        <state_interface name="position"/>
        <state_interface name="velocity"/>
    </joint>
    <!-- Drive wheels (6 wheels) -->
    <joint name="sol_on_teker">
        <command_interface name="velocity"/>
        <state_interface name="position"/>
        <state_interface name="velocity"/>
    </joint>
    <joint name="sol_orta_teker">
        <command_interface name="velocity"/>
        <state_interface name="position"/>
        <state_interface name="velocity"/>
    </joint>
    <joint name="sol_arka_teker">
        <command_interface name="velocity"/>
        <state_interface name="position"/>
        <state_interface name="velocity"/>
    </joint>
    <joint name="sag_on_teker">
        <command_interface name="velocity"/>
        <state_interface name="position"/>
        <state_interface name="velocity"/>
    </joint>
    <joint name="sag_orta_teker">
        <command_interface name="velocity"/>
        <state_interface name="position"/>
        <state_interface name="velocity"/>
    </joint>
    <joint name="sag_arka_teker">
        <command_interface name="velocity"/>
        <state_interface name="position"/>
        <state_interface name="velocity"/>
    </joint>
</ros2_control>

<!-- Transmissions for steering joints -->
<transmission name="sol_on_360_trans">
    <type>transmission_interface/SimpleTransmission</type>
    <joint name="sol_on_360">
        <hardwareInterface>hardware_interface/PositionJointInterface</hardwareInterface>
    </joint>
    <actuator name="sol_on_360_actuator">
        <hardwareInterface>hardware_interface/PositionJointInterface</hardwareInterface>
        <mechanicalReduction>1</mechanicalReduction>
    </actuator>
</transmission>

<transmission name="sag_on_360_trans">
    <type>transmission_interface/SimpleTransmission</type>
    <joint name="sag_on_360">
        <hardwareInterface>hardware_interface/PositionJointInterface</hardwareInterface>
    </joint>
    <actuator name="sag_on_360_actuator">
        <hardwareInterface>hardware_interface/PositionJointInterface</hardwareInterface>
        <mechanicalReduction>1</mechanicalReduction>
    </actuator>
</transmission>

<transmission name="sol_arka_360_trans">
    <type>transmission_interface/SimpleTransmission</type>
    <joint name="sol_arka_360">
        <hardwareInterface>hardware_interface/PositionJointInterface</hardwareInterface>
    </joint>
    <actuator name="sol_arka_360_actuator">
        <hardwareInterface>hardware_interface/PositionJointInterface</hardwareInterface>
        <mechanicalReduction>1</mechanicalReduction>
    </actuator>
</transmission>

<transmission name="sag_arka_360_trans">
    <type>transmission_interface/SimpleTransmission</type>
    <joint name="sag_arka_360">
        <hardwareInterface>hardware_interface/PositionJointInterface</hardwareInterface>
    </joint>
    <actuator name="sag_arka_360_actuator">
        <hardwareInterface>hardware_interface/PositionJointInterface</hardwareInterface>
        <mechanicalReduction>1</mechanicalReduction>
    </actuator>
</transmission>

<!-- Transmissions for drive wheels -->
<transmission name="sol_on_teker_trans">
    <type>transmission_interface/SimpleTransmission</type>
    <joint name="sol_on_teker">
        <hardwareInterface>hardware_interface/VelocityJointInterface</hardwareInterface>
    </joint>
    <actuator name="sol_on_teker_motor">
        <hardwareInterface>hardware_interface/VelocityJointInterface</hardwareInterface>
        <mechanicalReduction>1</mechanicalReduction>
    </actuator>
</transmission>

<transmission name="sol_orta_teker_trans">
    <type>transmission_interface/SimpleTransmission</type>
    <joint name="sol_orta_teker">
        <hardwareInterface>hardware_interface/VelocityJointInterface</hardwareInterface>
    </joint>
    <actuator name="sol_orta_teker_motor">
        <hardwareInterface>hardware_interface/VelocityJointInterface</hardwareInterface>
        <mechanicalReduction>1</mechanicalReduction>
    </actuator>
</transmission>

<transmission name="sol_arka_teker_trans">
    <type>transmission_interface/SimpleTransmission</type>
    <joint name="sol_arka_teker">
        <hardwareInterface>hardware_interface/VelocityJointInterface</hardwareInterface>
    </joint>
    <actuator name="sol_arka_teker_motor">
        <hardwareInterface>hardware_interface/VelocityJointInterface</hardwareInterface>
        <mechanicalReduction>1</mechanicalReduction>
    </actuator>
</transmission>

<transmission name="sag_on_teker_trans">
    <type>transmission_interface/SimpleTransmission</type>
    <joint name="sag_on_teker">
        <hardwareInterface>hardware_interface/VelocityJointInterface</hardwareInterface>
    </joint>
    <actuator name="sag_on_teker_motor">
        <hardwareInterface>hardware_interface/VelocityJointInterface</hardwareInterface>
        <mechanicalReduction>1</mechanicalReduction>
    </actuator>
</transmission>

<transmission name="sag_orta_teker_trans">
    <type>transmission_interface/SimpleTransmission</type>
    <joint name="sag_orta_teker">
        <hardwareInterface>hardware_interface/VelocityJointInterface</hardwareInterface>
    </joint>
    <actuator name="sag_orta_teker_motor">
        <hardwareInterface>hardware_interface/VelocityJointInterface</hardwareInterface>
        <mechanicalReduction>1</mechanicalReduction>
    </actuator>
</transmission>

<transmission name="sag_arka_teker_trans">
    <type>transmission_interface/SimpleTransmission</type>
    <joint name="sag_arka_teker">
        <hardwareInterface>hardware_interface/VelocityJointInterface</hardwareInterface>
    </joint>
    <actuator name="sag_arka_teker_motor">
        <hardwareInterface>hardware_interface/VelocityJointInterface</hardwareInterface>
        <mechanicalReduction>1</mechanicalReduction>
    </actuator>
</transmission>

<!-- Gazebo ROS2 Control Plugin -->
<gazebo>
    <plugin name="gazebo_ros2_control" filename="libgazebo_ros2_control.so">
        <parameters>$(find ika_controller)/config/controllers.yaml</parameters>
    </plugin>
</gazebo>

<gazebo>
    <plugin name="joint_state_publisher" filename="libgazebo_ros_joint_state_publisher.so">
        <ros>
            <remapping>~/out:=joint_states</remapping>
        </ros>
        <update_rate>30</update_rate>
    </plugin>
</gazebo>

</robot>